log/output_300_2022_CNN_gpu4.log
wandb: Currently logged in as: pqy000 (pqythu). Use `wandb login --relogin` to force relogin
GPU device ID: 4
newdata/300_2022.npy
0
2024-09-07 16:05:36.199043: I tensorflow/core/platform/cpu_feature_guard.cc:193] This TensorFlow binary is optimized with oneAPI Deep Neural Network Library (oneDNN) to use the following CPU instructions in performance-critical operations:  AVX2 FMA
To enable them in other operations, rebuild TensorFlow with the appropriate compiler flags.
2024-09-07 16:05:37.190350: W tensorflow/compiler/xla/stream_executor/platform/default/dso_loader.cc:64] Could not load dynamic library 'libnvinfer.so.7'; dlerror: libnvinfer.so.7: cannot open shared object file: No such file or directory; LD_LIBRARY_PATH: /opt/cudnn/lib64:/usr/local/cuda/lib64
2024-09-07 16:05:37.190448: W tensorflow/compiler/xla/stream_executor/platform/default/dso_loader.cc:64] Could not load dynamic library 'libnvinfer_plugin.so.7'; dlerror: libnvinfer_plugin.so.7: cannot open shared object file: No such file or directory; LD_LIBRARY_PATH: /opt/cudnn/lib64:/usr/local/cuda/lib64
2024-09-07 16:05:37.190461: W tensorflow/compiler/tf2tensorrt/utils/py_utils.cc:38] TF-TRT Warning: Cannot dlopen some TensorRT libraries. If you would like to use Nvidia GPU with TensorRT, please make sure the missing libraries mentioned above are installed properly.
wandb: wandb version 0.17.9 is available!  To upgrade, please run:
wandb:  $ pip install wandb --upgrade
wandb: Tracking run with wandb version 0.12.17
wandb: Run data is saved locally in /home/qingyi/GPU20/DeepLOB/wandb/run-20240907_160533-10ls7vcr
wandb: Run `wandb offline` to turn off syncing.
wandb: Syncing run CNN
wandb: ⭐️ View project at https://wandb.ai/pqythu/futures300
wandb: 🚀 View run at https://wandb.ai/pqythu/futures300/runs/10ls7vcr
Model(
  (conv1): Conv1d(10, 64, kernel_size=(3,), stride=(1,), padding=(1,))
  (conv2): Conv1d(64, 64, kernel_size=(3,), stride=(1,), padding=(1,))
  (pool): MaxPool1d(kernel_size=2, stride=2, padding=0, dilation=1, ceil_mode=False)
  (fc): Linear(in_features=512, out_features=5, bias=True)
)
number of parameters: 16901
Training start
epoch  1 | time used:  2.01s | train_loss 1.528 | valid loss 1.540 | valid acc 0.330 | mae 2.005 | mse 6.775 | rmse 2.60 | r2 -1.46 | sharp 0.00
epoch  2 | time used:  0.07s | train_loss 1.481 | valid loss 1.540 | valid acc 0.330 | mae 2.005 | mse 6.775 | rmse 2.60 | r2 -1.46 | sharp 0.00
epoch  3 | time used:  0.04s | train_loss 1.482 | valid loss 1.540 | valid acc 0.330 | mae 2.005 | mse 6.775 | rmse 2.60 | r2 -1.46 | sharp 0.00
epoch  4 | time used:  0.04s | train_loss 1.526 | valid loss 1.551 | valid acc 0.330 | mae 2.005 | mse 6.775 | rmse 2.60 | r2 -1.46 | sharp 0.00
epoch  5 | time used:  0.03s | train_loss 1.511 | valid loss 1.540 | valid acc 0.330 | mae 2.005 | mse 6.775 | rmse 2.60 | r2 -1.46 | sharp 0.00
epoch  6 | time used:  0.04s | train_loss 1.482 | valid loss 1.540 | valid acc 0.330 | mae 2.005 | mse 6.775 | rmse 2.60 | r2 -1.46 | sharp 0.00
epoch  7 | time used:  0.14s | train_loss 1.526 | valid loss 1.540 | valid acc 0.330 | mae 2.005 | mse 6.775 | rmse 2.60 | r2 -1.46 | sharp 0.00
epoch  8 | time used:  0.09s | train_loss 1.479 | valid loss 1.540 | valid acc 0.330 | mae 2.005 | mse 6.775 | rmse 2.60 | r2 -1.46 | sharp 0.00
epoch  9 | time used:  0.05s | train_loss 1.527 | valid loss 1.540 | valid acc 0.330 | mae 2.005 | mse 6.775 | rmse 2.60 | r2 -1.46 | sharp 0.00
epoch 10 | time used:  0.04s | train_loss 1.491 | valid loss 1.540 | valid acc 0.330 | mae 2.005 | mse 6.775 | rmse 2.60 | r2 -1.46 | sharp 0.00
saving the model to ./save/2022_300/CNN/checkpoint10.pt
epoch 11 | time used:  0.04s | train_loss 1.496 | valid loss 1.540 | valid acc 0.330 | mae 2.005 | mse 6.775 | rmse 2.60 | r2 -1.46 | sharp 0.00
epoch 12 | time used:  0.05s | train_loss 1.483 | valid loss 1.540 | valid acc 0.330 | mae 2.005 | mse 6.775 | rmse 2.60 | r2 -1.46 | sharp 0.00
epoch 13 | time used:  0.04s | train_loss 1.525 | valid loss 1.540 | valid acc 0.330 | mae 2.005 | mse 6.775 | rmse 2.60 | r2 -1.46 | sharp 0.00
epoch 14 | time used:  0.04s | train_loss 1.501 | valid loss 1.540 | valid acc 0.330 | mae 2.005 | mse 6.775 | rmse 2.60 | r2 -1.46 | sharp 0.00
epoch 15 | time used:  0.04s | train_loss 1.513 | valid loss 1.540 | valid acc 0.330 | mae 2.005 | mse 6.775 | rmse 2.60 | r2 -1.46 | sharp 0.00
epoch 16 | time used:  0.04s | train_loss 1.461 | valid loss 1.540 | valid acc 0.330 | mae 2.005 | mse 6.775 | rmse 2.60 | r2 -1.46 | sharp 0.00
epoch 17 | time used:  0.04s | train_loss 1.496 | valid loss 1.540 | valid acc 0.330 | mae 2.005 | mse 6.775 | rmse 2.60 | r2 -1.46 | sharp 0.00
epoch 18 | time used:  0.04s | train_loss 1.478 | valid loss 1.540 | valid acc 0.330 | mae 2.005 | mse 6.775 | rmse 2.60 | r2 -1.46 | sharp 0.00
epoch 19 | time used:  0.05s | train_loss 1.492 | valid loss 1.523 | valid acc 0.330 | mae 2.005 | mse 6.775 | rmse 2.60 | r2 -1.46 | sharp 0.00
epoch 20 | time used:  0.05s | train_loss 1.512 | valid loss 1.540 | valid acc 0.330 | mae 2.005 | mse 6.775 | rmse 2.60 | r2 -1.46 | sharp 0.00
saving the model to ./save/2022_300/CNN/checkpoint20.pt
epoch 21 | time used:  0.05s | train_loss 1.480 | valid loss 1.540 | valid acc 0.330 | mae 2.005 | mse 6.775 | rmse 2.60 | r2 -1.46 | sharp 0.00
epoch 22 | time used:  0.04s | train_loss 1.488 | valid loss 1.540 | valid acc 0.330 | mae 2.005 | mse 6.775 | rmse 2.60 | r2 -1.46 | sharp 0.00
epoch 23 | time used:  0.04s | train_loss 1.462 | valid loss 1.540 | valid acc 0.330 | mae 2.005 | mse 6.775 | rmse 2.60 | r2 -1.46 | sharp 0.00
epoch 24 | time used:  0.04s | train_loss 1.514 | valid loss 1.540 | valid acc 0.330 | mae 2.005 | mse 6.775 | rmse 2.60 | r2 -1.46 | sharp 0.00
epoch 25 | time used:  0.04s | train_loss 1.499 | valid loss 1.540 | valid acc 0.330 | mae 2.005 | mse 6.775 | rmse 2.60 | r2 -1.46 | sharp 0.00
epoch 26 | time used:  0.04s | train_loss 1.485 | valid loss 1.540 | valid acc 0.330 | mae 2.005 | mse 6.775 | rmse 2.60 | r2 -1.46 | sharp 0.00
epoch 27 | time used:  0.04s | train_loss 1.498 | valid loss 1.540 | valid acc 0.330 | mae 2.005 | mse 6.775 | rmse 2.60 | r2 -1.46 | sharp 0.00
epoch 28 | time used:  0.04s | train_loss 1.515 | valid loss 1.561 | valid acc 0.310 | mae 1.995 | mse 6.735 | rmse 2.60 | r2 -1.44 | sharp 1.66
epoch 29 | time used:  0.04s | train_loss 1.536 | valid loss 1.561 | valid acc 0.310 | mae 1.995 | mse 6.735 | rmse 2.60 | r2 -1.44 | sharp 1.66
epoch 30 | time used:  0.05s | train_loss 1.560 | valid loss 1.561 | valid acc 0.310 | mae 1.995 | mse 6.735 | rmse 2.60 | r2 -1.44 | sharp 1.66
saving the model to ./save/2022_300/CNN/checkpoint30.pt
epoch 31 | time used:  0.04s | train_loss 1.522 | valid loss 1.540 | valid acc 0.330 | mae 2.005 | mse 6.775 | rmse 2.60 | r2 -1.46 | sharp 0.00
epoch 32 | time used:  0.04s | train_loss 1.456 | valid loss 1.540 | valid acc 0.330 | mae 2.005 | mse 6.775 | rmse 2.60 | r2 -1.46 | sharp 0.00
epoch 33 | time used:  0.05s | train_loss 1.511 | valid loss 1.540 | valid acc 0.330 | mae 2.005 | mse 6.775 | rmse 2.60 | r2 -1.46 | sharp 0.00
epoch 34 | time used:  0.05s | train_loss 1.469 | valid loss 1.540 | valid acc 0.330 | mae 2.005 | mse 6.775 | rmse 2.60 | r2 -1.46 | sharp 0.00
epoch 35 | time used:  0.04s | train_loss 1.479 | valid loss 1.540 | valid acc 0.330 | mae 2.005 | mse 6.775 | rmse 2.60 | r2 -1.46 | sharp 0.00
epoch 36 | time used:  0.04s | train_loss 1.513 | valid loss 1.540 | valid acc 0.330 | mae 2.005 | mse 6.775 | rmse 2.60 | r2 -1.46 | sharp 0.00
epoch 37 | time used:  0.04s | train_loss 1.513 | valid loss 1.540 | valid acc 0.330 | mae 2.005 | mse 6.775 | rmse 2.60 | r2 -1.46 | sharp 0.00
epoch 38 | time used:  0.04s | train_loss 1.459 | valid loss 1.540 | valid acc 0.330 | mae 2.005 | mse 6.775 | rmse 2.60 | r2 -1.46 | sharp 0.00
epoch 39 | time used:  0.04s | train_loss 1.511 | valid loss 1.540 | valid acc 0.330 | mae 2.005 | mse 6.775 | rmse 2.60 | r2 -1.46 | sharp 0.00
