log/output_300_2022_GRU_gpu2.log
wandb: W&B API key is configured. Use `wandb login --relogin` to force relogin
GPU device ID: 2
newdata/300_2022.npy
0
wandb: wandb version 0.17.9 is available!  To upgrade, please run:
wandb:  $ pip install wandb --upgrade
wandb: Tracking run with wandb version 0.12.17
wandb: Run data is saved locally in /home/qingyi/GPU20/DeepLOB/wandb/run-20240907_113515-3fwffk7h
wandb: Run `wandb offline` to turn off syncing.
wandb: Syncing run GRU
wandb: ⭐️ View project at https://wandb.ai/pqythu/futures300
wandb: 🚀 View run at https://wandb.ai/pqythu/futures300/runs/3fwffk7h
2024-09-07 11:35:22.042053: I tensorflow/core/platform/cpu_feature_guard.cc:193] This TensorFlow binary is optimized with oneAPI Deep Neural Network Library (oneDNN) to use the following CPU instructions in performance-critical operations:  AVX2 FMA
To enable them in other operations, rebuild TensorFlow with the appropriate compiler flags.
2024-09-07 11:35:23.308672: W tensorflow/compiler/xla/stream_executor/platform/default/dso_loader.cc:64] Could not load dynamic library 'libnvinfer.so.7'; dlerror: libnvinfer.so.7: cannot open shared object file: No such file or directory; LD_LIBRARY_PATH: /opt/cudnn/lib64:/usr/local/cuda/lib64
2024-09-07 11:35:23.308829: W tensorflow/compiler/xla/stream_executor/platform/default/dso_loader.cc:64] Could not load dynamic library 'libnvinfer_plugin.so.7'; dlerror: libnvinfer_plugin.so.7: cannot open shared object file: No such file or directory; LD_LIBRARY_PATH: /opt/cudnn/lib64:/usr/local/cuda/lib64
2024-09-07 11:35:23.308853: W tensorflow/compiler/tf2tensorrt/utils/py_utils.cc:38] TF-TRT Warning: Cannot dlopen some TensorRT libraries. If you would like to use Nvidia GPU with TensorRT, please make sure the missing libraries mentioned above are installed properly.
Model(
  (rnn): GRU(10, 64, batch_first=True)
  (fc): Linear(in_features=64, out_features=5, bias=True)
)
number of parameters: 14917
Training start
epoch  1 | time used:  1.58s | train_loss 1.504 | valid loss 1.510 | valid acc 0.331 | mae 2.013 | mse 6.885 | rmse 2.62 | r2 -1.43 | sharp 1.79
epoch  2 | time used:  0.29s | train_loss 1.539 | valid loss 1.475 | valid acc 0.338 | mae 1.988 | mse 6.785 | rmse 2.60 | r2 -1.39 | sharp 0.00
epoch  3 | time used:  0.22s | train_loss 1.510 | valid loss 1.509 | valid acc 0.331 | mae 2.013 | mse 6.885 | rmse 2.62 | r2 -1.43 | sharp 1.79
epoch  4 | time used:  0.17s | train_loss 1.491 | valid loss 1.509 | valid acc 0.331 | mae 2.013 | mse 6.885 | rmse 2.62 | r2 -1.43 | sharp 1.79
epoch  5 | time used:  0.16s | train_loss 1.500 | valid loss 1.475 | valid acc 0.338 | mae 1.988 | mse 6.785 | rmse 2.60 | r2 -1.39 | sharp 0.00
epoch  6 | time used:  0.17s | train_loss 1.492 | valid loss 1.509 | valid acc 0.331 | mae 2.013 | mse 6.885 | rmse 2.62 | r2 -1.43 | sharp 1.79
epoch  7 | time used:  0.21s | train_loss 1.525 | valid loss 1.509 | valid acc 0.331 | mae 2.013 | mse 6.885 | rmse 2.62 | r2 -1.43 | sharp 1.79
epoch  8 | time used:  0.21s | train_loss 1.510 | valid loss 1.476 | valid acc 0.338 | mae 1.988 | mse 6.785 | rmse 2.60 | r2 -1.39 | sharp 0.00
epoch  9 | time used:  0.20s | train_loss 1.496 | valid loss 1.509 | valid acc 0.331 | mae 2.013 | mse 6.885 | rmse 2.62 | r2 -1.43 | sharp 1.79
epoch 10 | time used:  0.20s | train_loss 1.495 | valid loss 1.509 | valid acc 0.331 | mae 2.013 | mse 6.885 | rmse 2.62 | r2 -1.43 | sharp 1.79
saving the model to ./save/2022_300/GRU/checkpoint10.pt
epoch 11 | time used:  0.20s | train_loss 1.497 | valid loss 1.823 | valid acc 0.080 | mae 1.675 | mse 3.860 | rmse 1.96 | r2 -0.36 | sharp 1.79
epoch 12 | time used:  0.20s | train_loss 1.524 | valid loss 1.475 | valid acc 0.338 | mae 1.988 | mse 6.785 | rmse 2.60 | r2 -1.39 | sharp 0.00
epoch 13 | time used:  0.17s | train_loss 1.506 | valid loss 1.475 | valid acc 0.338 | mae 1.988 | mse 6.785 | rmse 2.60 | r2 -1.39 | sharp 0.00
epoch 14 | time used:  0.19s | train_loss 1.494 | valid loss 1.509 | valid acc 0.331 | mae 2.013 | mse 6.885 | rmse 2.62 | r2 -1.43 | sharp 1.79
epoch 15 | time used:  0.18s | train_loss 1.503 | valid loss 1.475 | valid acc 0.338 | mae 1.988 | mse 6.785 | rmse 2.60 | r2 -1.39 | sharp 0.00
epoch 16 | time used:  0.18s | train_loss 1.495 | valid loss 1.475 | valid acc 0.338 | mae 1.988 | mse 6.785 | rmse 2.60 | r2 -1.39 | sharp 0.00
epoch 17 | time used:  0.16s | train_loss 1.509 | valid loss 1.477 | valid acc 0.338 | mae 1.988 | mse 6.785 | rmse 2.60 | r2 -1.39 | sharp 0.00
epoch 18 | time used:  0.15s | train_loss 1.497 | valid loss 1.509 | valid acc 0.331 | mae 2.013 | mse 6.885 | rmse 2.62 | r2 -1.43 | sharp 1.79
epoch 19 | time used:  0.18s | train_loss 1.489 | valid loss 1.509 | valid acc 0.331 | mae 2.013 | mse 6.885 | rmse 2.62 | r2 -1.43 | sharp 1.79
epoch 20 | time used:  0.16s | train_loss 1.490 | valid loss 1.475 | valid acc 0.338 | mae 1.988 | mse 6.785 | rmse 2.60 | r2 -1.39 | sharp 0.00
saving the model to ./save/2022_300/GRU/checkpoint20.pt
epoch 21 | time used:  0.17s | train_loss 1.514 | valid loss 1.476 | valid acc 0.338 | mae 1.988 | mse 6.785 | rmse 2.60 | r2 -1.39 | sharp 0.00
epoch 22 | time used:  0.18s | train_loss 1.510 | valid loss 1.509 | valid acc 0.331 | mae 2.013 | mse 6.885 | rmse 2.62 | r2 -1.43 | sharp 1.79
epoch 23 | time used:  0.18s | train_loss 1.491 | valid loss 1.509 | valid acc 0.331 | mae 2.013 | mse 6.885 | rmse 2.62 | r2 -1.43 | sharp 1.79
epoch 24 | time used:  0.20s | train_loss 1.514 | valid loss 1.476 | valid acc 0.338 | mae 1.988 | mse 6.785 | rmse 2.60 | r2 -1.39 | sharp 0.00
epoch 25 | time used:  0.20s | train_loss 1.497 | valid loss 1.509 | valid acc 0.331 | mae 2.013 | mse 6.885 | rmse 2.62 | r2 -1.43 | sharp 1.79
epoch 26 | time used:  0.20s | train_loss 1.490 | valid loss 1.508 | valid acc 0.331 | mae 2.013 | mse 6.885 | rmse 2.62 | r2 -1.43 | sharp 1.79
epoch 27 | time used:  0.20s | train_loss 1.502 | valid loss 1.475 | valid acc 0.338 | mae 1.988 | mse 6.785 | rmse 2.60 | r2 -1.39 | sharp 0.00
epoch 28 | time used:  0.20s | train_loss 1.497 | valid loss 1.509 | valid acc 0.331 | mae 2.013 | mse 6.885 | rmse 2.62 | r2 -1.43 | sharp 1.79
epoch 29 | time used:  0.21s | train_loss 1.507 | valid loss 1.476 | valid acc 0.338 | mae 1.988 | mse 6.785 | rmse 2.60 | r2 -1.39 | sharp 0.00
epoch 30 | time used:  0.19s | train_loss 1.498 | valid loss 1.509 | valid acc 0.331 | mae 2.013 | mse 6.885 | rmse 2.62 | r2 -1.43 | sharp 1.79
saving the model to ./save/2022_300/GRU/checkpoint30.pt
epoch 31 | time used:  0.19s | train_loss 1.488 | valid loss 1.475 | valid acc 0.338 | mae 1.988 | mse 6.785 | rmse 2.60 | r2 -1.39 | sharp 0.00
epoch 32 | time used:  0.20s | train_loss 1.510 | valid loss 1.476 | valid acc 0.338 | mae 1.988 | mse 6.785 | rmse 2.60 | r2 -1.39 | sharp 0.00
epoch 33 | time used:  0.19s | train_loss 1.494 | valid loss 1.509 | valid acc 0.331 | mae 2.013 | mse 6.885 | rmse 2.62 | r2 -1.43 | sharp 1.79
epoch 34 | time used:  0.18s | train_loss 1.495 | valid loss 1.475 | valid acc 0.338 | mae 1.988 | mse 6.785 | rmse 2.60 | r2 -1.39 | sharp 0.00
epoch 35 | time used:  0.21s | train_loss 1.508 | valid loss 1.476 | valid acc 0.338 | mae 1.988 | mse 6.785 | rmse 2.60 | r2 -1.39 | sharp 0.00
epoch 36 | time used:  0.20s | train_loss 1.475 | valid loss 1.509 | valid acc 0.331 | mae 2.013 | mse 6.885 | rmse 2.62 | r2 -1.43 | sharp 1.79
epoch 37 | time used:  0.20s | train_loss 1.494 | valid loss 1.476 | valid acc 0.338 | mae 1.988 | mse 6.785 | rmse 2.60 | r2 -1.39 | sharp 0.00
epoch 38 | time used:  0.20s | train_loss 1.508 | valid loss 1.509 | valid acc 0.331 | mae 2.013 | mse 6.885 | rmse 2.62 | r2 -1.43 | sharp 1.79
epoch 39 | time used:  0.20s | train_loss 1.494 | valid loss 1.527 | valid acc 0.331 | mae 2.013 | mse 6.885 | rmse 2.62 | r2 -1.43 | sharp 1.79
epoch 40 | time used:  0.17s | train_loss 1.490 | valid loss 1.509 | valid acc 0.331 | mae 2.013 | mse 6.885 | rmse 2.62 | r2 -1.43 | sharp 1.79
saving the model to ./save/2022_300/GRU/checkpoint40.pt
